Workbook

Sheet Instructions
A1: Supplier Quotation Compliance & Evaluation - Phase 1
A2: Compare like-for-like before comparing price. Rules classify; humans approve exceptions and award.
A4: HOW TO USE
A5: 1. Baseline | B5: RFQ header, BOQ items, and requirement lines (class, rule, target, tolerance, fail result).
A6: 2. Submissions | B6: One row per supplier + revision + baseline line. Offered value + supplier declaration. New revision = new rows; never overwrite.
A7: 3. Exceptions | B7: Log every YELLOW/RED line needing a decision. Only Decision = Accepted with an Approver name clears a line.
A8: 4. Compliance Matrix | B8: Supplier names in row 4 (max 8). Latest revision is picked up automatically.
A9: 5. Evaluation | B9: Enter unit rates per BOQ item. Totals use RFQ quantities. Only eligible suppliers are ranked.
A10: 6. Approval | B10: Sign-offs. Award status turns APPROVED only when every role approves.
A12: COLOUR LEGEND
A13: Blue text | B13: Input - edit these cells
A14: Black text | B14: Formula - do not edit
A15: Grey fill | B15: Lookup from Baseline - do not edit
A16: Yellow fill | B16: Key assumption - confirm before use
A18: STATUS LOGIC
A19: GREEN | B19: Meets baseline (or Informational).
A20: YELLOW | B20: Within tolerance, alternative/partial declaration, brand/spec equivalence, or value not stated on an Evaluated line.
A21: RED | B21: Fails a mandatory requirement, mandatory value missing, or declared Non-Compliant.
A22: CLEARED | B22: YELLOW/RED line accepted through a logged exception with approver.
A23: Supplier eligible | B23: YES only when the latest revision has no open RED/YELLOW lines and no missing lines.
A25: SAMPLE EXERCISE
A26: Data | B26: RFQ P01113, aluminium works, Diyar 33 (Qairawan). 7 quotations keyed from the PDFs against the RFQ spec sheets.
A27: Declaration | B27: Quotations carry no structured declarations. "Fully Compliant" = supplier stated the value; "Not Stated" = absent from the quotation.
A28: Check before use | B28: Offered values are my reading of the PDFs (Arabic OCR). Verify against originals. Validity target (15-Oct-2026) is an assumption.
A29: Out of scope | B29: AI extraction, confidence scores, supplier portal and Odoo integration (Phases 2-4).

Sheet Baseline
A1: RFQ Baseline
A3: RFQ ID | B3: P01113
A4: Title | B4: Aluminium works supply & install - Diyar 33 (Qairawan)
A5: Baseline version | B5: v1
A6: Issue date | B6: 46285
A7: Approved by
A8: Change note | B8: Initial issue
A9: AI confidence threshold | B9: 0.8 | C9: Lines below this need human review
A10: Item | B10: Description | C10: Unit | D10: Qty
A11: 1 | B11: Aluminium sliding windows, Saraya 12 cm, 1.5 mm [001386] | C11: m2 | D11: 504
A12: 2 | B12: Aluminium hinged doors [8670] | C12: m2 | D12: 23
A13: 3 | B13: Skylight | C13: m2 | D13: 7
A17: RFQ PDF shows item 1 unit as "Units"; quotations and the comparison sheet use m2. Confirm.
A19: Line | B19: Parameter | C19: Class | D19: Rule | E19: Target | F19: Tolerance | G19: Fail result | H19: Notes
A20: 1 | B20: Item 1 priced (windows) | C20: Mandatory | D20: Exact | E20: Yes | G20: RED | H20: RFQ P01113 item 1
A21: 2 | B21: Item 2 priced (doors) | C21: Mandatory | D21: Exact | E21: Yes | G21: RED | H21: RFQ P01113 item 2
A22: 3 | B22: Item 3 priced (skylight) | C22: Mandatory | D22: Exact | E22: Yes | G22: RED | H22: RFQ P01113 item 3
A23: 4 | B23: Offer valid until | C23: Evaluated | D23: Min | E23: 46310 | F23: 0 | G23: YELLOW | H23: ASSUMPTION: must cover award window - confirm date
A24: 5 | B24: Quotation date (on/after RFQ date) | C24: Evaluated | D24: Min | E24: 46285 | F24: 0 | G24: YELLOW | H24: RFQ date 20-Sep-2026
A25: 6 | B25: Prices stated ex-VAT | C25: Evaluated | D25: Exact | E25: Ex-VAT | G25: YELLOW | H25: Needed for like-for-like
A26: 7 | B26: Accessories origin | C26: Evaluated | D26: Exact | E26: Italian | G26: YELLOW | H26: Spec s4: original Italian
A27: 8 | B27: Silicone brand | C27: Evaluated | D27: Exact | E27: Wacker GP | G27: YELLOW | H27: Spec s5: Wacker GP
A28: 9 | B28: Rubber / gasket brand | C28: Evaluated | D28: Exact | E28: ALPHA | G28: YELLOW | H28: Spec s5: ALPHA
A29: 10 | B29: Advance payment at signing (%) | C29: Informational | D29: Max | G29: YELLOW | H29: Captured for comparison only
A30: 11 | B30: Windows: frame depth (cm) | C30: Mandatory | D30: Min | E30: 12 | F30: 0 | G30: RED | H30: Spec s2: 12 cm
A31: 12 | B31: Windows: profile thickness (mm) | C31: Mandatory | D31: Min | E31: 1.5 | F31: 0 | G31: RED | H31: Spec s2: min 1.5 mm
A32: 13 | B32: Windows: glass total thickness (mm) | C32: Mandatory | D32: Min | E32: 24 | F32: 0 | G32: RED | H32: Spec s3: 6+12+6 = 24 mm
A33: 14 | B33: Windows: glass tempered (securit) | C33: Evaluated | D33: Exact | E33: Yes | G33: YELLOW | H33: Spec s3
A34: 15 | B34: Windows: glass HD / reflective | C34: Evaluated | D34: Exact | E34: Yes | G34: YELLOW | H34: Spec s3: reflective HD
A35: 16 | B35: Windows: fly screen included | C35: Evaluated | D35: Exact | E35: Yes | G35: YELLOW | H35: Spec s4
A36: 17 | B36: Windows/doors: warranty (years) | C36: Evaluated | D36: Min | E36: 5 | F36: 0 | G36: YELLOW | H36: Spec s8: 5 yrs, chamber certified
A37: 18 | B37: Doors: profile thickness (mm) | C37: Mandatory | D37: Min | E37: 1.5 | F37: 0 | G37: RED | H37: Spec s2: min 1.5 mm
A38: 19 | B38: Doors: glass total thickness (mm) | C38: Mandatory | D38: Min | E38: 24 | F38: 0 | G38: RED | H38: Spec s3: 24 mm
A39: 20 | B39: Skylight: structure thickness (mm) | C39: Mandatory | D39: Min | E39: 3 | F39: 0 | G39: RED | H39: Skylight spec s2: min 3 mm
A40: 21 | B40: Skylight: glass total thickness (mm) | C40: Mandatory | D40: Min | E40: 24 | F40: 0 | G40: RED | H40: Skylight spec s3: 24 mm
A41: 22 | B41: Skylight: glass tempered | C41: Evaluated | D41: Exact | E41: Yes | G41: YELLOW | H41: Skylight spec s3
A42: 23 | B42: Skylight: structural silicone | C42: Evaluated | D42: Exact | E42: DC 995 or equivalent | G42: YELLOW | H42: Skylight spec s4: equivalence needs technical approval
A43: 24 | B43: Skylight: warranty (years) | C43: Evaluated | D43: Min | E43: 10 | F43: 0 | G43: YELLOW | H43: Skylight spec s6: 10 yrs
A51: Rules: Min = offered >= target | Max = offered <= target | Range = target +/- tolerance | Exact = text match. Tolerance gives a YELLOW band; beyond it the Fail result applies.

Sheet Submissions
A1: Supplier Submissions (append-only)
A2: One row per supplier / revision / baseline line. Columns N-Q are helpers.
A4: Supplier | B4: Rev | C4: Line | D4: Parameter | E4: Class | F4: Required | G4: Offered | H4: Declaration | I4: Justification | J4: Rule result | K4: Review class | L4: Final status | M4: Flag | N4: Rule | O4: Tol | P4: Fail | Q4: Key | R4: AI conf. | S4: Source (page: quote)
D5: =IF($A5="","",IFERROR(INDEX(Baseline!$B$20:$B$49,MATCH($C5,Baseline!$A$20:$A$49,0)),"Line not in baseline")) | E5: =IF($A5="","",IFERROR(INDEX(Baseline!$C$20:$C$49,MATCH($C5,Baseline!$A$20:$A$49,0)),"")) | F5: =IF($A5="","",IFERROR(INDEX(Baseline!$E$20:$E$49,MATCH($C5,Baseline!$A$20:$A$49,0)),"")) | J5: =IF($A5="","",IF($E5="Informational","GREEN",IF($G5="",IF($E5="Mandatory","RED","YELLOW"),IF($N5="Exact",IF(UPPER(TRIM($G5&""))=UPPER(TRIM($F5&"")),"GREEN",$P5),IF(NOT(ISNUMBER($G5)),$P5,IF($N5="Min",IF($G5>=$F5,"GREEN",IF($G5>=$F5-$O5,"YELLOW",$P5)),IF($N5="Max",IF($G5<=$F5,"GREEN",IF($G5<=$F5+$O5,"YELLOW",$P5)),IF($N5="Range",IF(ABS($G5-$F5)<=$O5,"GREEN",$P5),"CHECK RULE")))))))) | K5: =IF($A5="","",IF($H5="Non-Compliant","RED",IF(AND(OR($H5="Alternative Offer",$H5="Partially Compliant"),$J5="GREEN"),"YELLOW",IF(AND($J5="GREEN",ISNUMBER($R5),$R5<Baseline!$B$9),"YELLOW",$J5)))) | L5: =IF($A5="","",IF($K5="GREEN","GREEN",IF(COUNTIFS(Exceptions!$B$5:$B$104,$A5,Exceptions!$C$5:$C$104,$B5,Exceptions!$D$5:$D$104,$C5,Exceptions!$G$5:$G$104,"Accepted",Exceptions!$H$5:$H$104,"<>")>0,"CLEARED",$K5))) | M5: =IF($A5="","",IF($H5="","Declaration missing",IF($H5="Not Stated","Not stated in quotation",IF(AND(ISNUMBER($R5),$R5<Baseline!$B$9),"Low AI confidence - verify",IF(AND($H5="Fully Compliant",$J5<>"GREEN"),"Declared Fully - evidence differs",""))))) | N5: =IF($A5="","",IFERROR(INDEX(Baseline!$D$20:$D$49,MATCH($C5,Baseline!$A$20:$A$49,0)),"")) | O5: =IF($A5="","",IFERROR(INDEX(Baseline!$F$20:$F$49,MATCH($C5,Baseline!$A$20:$A$49,0)),0)) | P5: =IF($A5="","",IFERROR(INDEX(Baseline!$G$20:$G$49,MATCH($C5,Baseline!$A$20:$A$49,0)),"RED")) | Q5: =IF($A5="","",$A5&"|"&$B5&"|"&$C5)
D6: =IF($A6="","",IFERROR(INDEX(Baseline!$B$20:$B$49,MATCH($C6,Baseline!$A$20:$A$49,0)),"Line not in baseline")) | E6: =IF($A6="","",IFERROR(INDEX(Baseline!$C$20:$C$49,MATCH($C6,Baseline!$A$20:$A$49,0)),"")) | F6: =IF($A6="","",IFERROR(INDEX(Baseline!$E$20:$E$49,MATCH($C6,Baseline!$A$20:$A$49,0)),"")) | J6: =IF($A6="","",IF($E6="Informational","GREEN",IF($G6="",IF($E6="Mandatory","RED","YELLOW"),IF($N6="Exact",IF(UPPER(TRIM($G6&""))=UPPER(TRIM($F6&"")),"GREEN",$P6),IF(NOT(ISNUMBER($G6)),$P6,IF($N6="Min",IF($G6>=$F6,"GREEN",IF($G6>=$F6-$O6,"YELLOW",$P6)),IF($N6="Max",IF($G6<=$F6,"GREEN",IF($G6<=$F6+$O6,"YELLOW",$P6)),IF($N6="Range",IF(ABS($G6-$F6)<=$O6,"GREEN",$P6),"CHECK RULE")))))))) | K6: =IF($A6="","",IF($H6="Non-Compliant","RED",IF(AND(OR($H6="Alternative Offer",$H6="Partially Compliant"),$J6="GREEN"),"YELLOW",IF(AND($J6="GREEN",ISNUMBER($R6),$R6<Baseline!$B$9),"YELLOW",$J6)))) | L6: =IF($A6="","",IF($K6="GREEN","GREEN",IF(COUNTIFS(Exceptions!$B$5:$B$104,$A6,Exceptions!$C$5:$C$104,$B6,Exceptions!$D$5:$D$104,$C6,Exceptions!$G$5:$G$104,"Accepted",Exceptions!$H$5:$H$104,"<>")>0,"CLEARED",$K6))) | M6: =IF($A6="","",IF($H6="","Declaration missing",IF($H6="Not Stated","Not stated in quotation",IF(AND(ISNUMBER($R6),$R6<Baseline!$B$9),"Low AI confidence - verify",IF(AND($H6="Fully Compliant",$J6<>"GREEN"),"Declared Fully - evidence differs",""))))) | N6: =IF($A6="","",IFERROR(INDEX(Baseline!$D$20:$D$49,MATCH($C6,Baseline!$A$20:$A$49,0)),"")) | O6: =IF($A6="","",IFERROR(INDEX(Baseline!$F$20:$F$49,MATCH($C6,Baseline!$A$20:$A$49,0)),0)) | P6: =IF($A6="","",IFERROR(INDEX(Baseline!$G$20:$G$49,MATCH($C6,Baseline!$A$20:$A$49,0)),"RED")) | Q6: =IF($A6="","",$A6&"|"&$B6&"|"&$C6)
D7: =IF($A7="","",IFERROR(INDEX(Baseline!$B$20:$B$49,MATCH($C7,Baseline!$A$20:$A$49,0)),"Line not in baseline")) | E7: =IF($A7="","",IFERROR(INDEX(Baseline!$C$20:$C$49,MATCH($C7,Baseline!$A$20:$A$49,0)),"")) | F7: =IF($A7="","",IFERROR(INDEX(Baseline!$E$20:$E$49,MATCH($C7,Baseline!$A$20:$A$49,0)),"")) | J7: =IF($A7="","",IF($E7="Informational","GREEN",IF($G7="",IF($E7="Mandatory","RED","YELLOW"),IF($N7="Exact",IF(UPPER(TRIM($G7&""))=UPPER(TRIM($F7&"")),"GREEN",$P7),IF(NOT(ISNUMBER($G7)),$P7,IF($N7="Min",IF($G7>=$F7,"GREEN",IF($G7>=$F7-$O7,"YELLOW",$P7)),IF($N7="Max",IF($G7<=$F7,"GREEN",IF($G7<=$F7+$O7,"YELLOW",$P7)),IF($N7="Range",IF(ABS($G7-$F7)<=$O7,"GREEN",$P7),"CHECK RULE")))))))) | K7: =IF($A7="","",IF($H7="Non-Compliant","RED",IF(AND(OR($H7="Alternative Offer",$H7="Partially Compliant"),$J7="GREEN"),"YELLOW",IF(AND($J7="GREEN",ISNUMBER($R7),$R7<Baseline!$B$9),"YELLOW",$J7)))) | L7: =IF($A7="","",IF($K7="GREEN","GREEN",IF(COUNTIFS(Exceptions!$B$5:$B$104,$A7,Exceptions!$C$5:$C$104,$B7,Exceptions!$D$5:$D$104,$C7,Exceptions!$G$5:$G$104,"Accepted",Exceptions!$H$5:$H$104,"<>")>0,"CLEARED",$K7))) | M7: =IF($A7="","",IF($H7="","Declaration missing",IF($H7="Not Stated","Not stated in quotation",IF(AND(ISNUMBER($R7),$R7<Baseline!$B$9),"Low AI confidence - verify",IF(AND($H7="Fully Compliant",$J7<>"GREEN"),"Declared Fully - evidence differs",""))))) | N7: =IF($A7="","",IFERROR(INDEX(Baseline!$D$20:$D$49,MATCH($C7,Baseline!$A$20:$A$49,0)),"")) | O7: =IF($A7="","",IFERROR(INDEX(Baseline!$F$20:$F$49,MATCH($C7,Baseline!$A$20:$A$49,0)),0)) | P7: =IF($A7="","",IFERROR(INDEX(Baseline!$G$20:$G$49,MATCH($C7,Baseline!$A$20:$A$49,0)),"RED")) | Q7: =IF($A7="","",$A7&"|"&$B7&"|"&$C7)
D8: =IF($A8="","",IFERROR(INDEX(Baseline!$B$20:$B$49,MATCH($C8,Baseline!$A$20:$A$49,0)),"Line not in baseline")) | E8: =IF($A8="","",IFERROR(INDEX(Baseline!$C$20:$C$49,MATCH($C8,Baseline!$A$20:$A$49,0)),"")) | F8: =IF($A8="","",IFERROR(INDEX(Baseline!$E$20:$E$49,MATCH($C8,Baseline!$A$20:$A$49,0)),"")) | J8: =IF($A8="","",IF($E8="Informational","GREEN",IF($G8="",IF($E8="Mandatory","RED","YELLOW"),IF($N8="Exact",IF(UPPER(TRIM($G8&""))=UPPER(TRIM($F8&"")),"GREEN",$P8),IF(NOT(ISNUMBER($G8)),$P8,IF($N8="Min",IF($G8>=$F8,"GREEN",IF($G8>=$F8-$O8,"YELLOW",$P8)),IF($N8="Max",IF($G8<=$F8,"GREEN",IF($G8<=$F8+$O8,"YELLOW",$P8)),IF($N8="Range",IF(ABS($G8-$F8)<=$O8,"GREEN",$P8),"CHECK RULE")))))))) | K8: =IF($A8="","",IF($H8="Non-Compliant","RED",IF(AND(OR($H8="Alternative Offer",$H8="Partially Compliant"),$J8="GREEN"),"YELLOW",IF(AND($J8="GREEN",ISNUMBER($R8),$R8<Baseline!$B$9),"YELLOW",$J8)))) | L8: =IF($A8="","",IF($K8="GREEN","GREEN",IF(COUNTIFS(Exceptions!$B$5:$B$104,$A8,Exceptions!$C$5:$C$104,$B8,Exceptions!$D$5:$D$104,$C8,Exceptions!$G$5:$G$104,"Accepted",Exceptions!$H$5:$H$104,"<>")>0,"CLEARED",$K8))) | M8: =IF($A8="","",IF($H8="","Declaration missing",IF($H8="Not Stated","Not stated in quotation",IF(AND(ISNUMBER($R8),$R8<Baseline!$B$9),"Low AI confidence - verify",IF(AND($H8="Fully Compliant",$J8<>"GREEN"),"Declared Fully - evidence differs",""))))) | N8: =IF($A8="","",IFERROR(INDEX(Baseline!$D$20:$D$49,MATCH($C8,Baseline!$A$20:$A$49,0)),"")) | O8: =IF($A8="","",IFERROR(INDEX(Baseline!$F$20:$F$49,MATCH($C8,Baseline!$A$20:$A$49,0)),0)) | P8: =IF($A8="","",IFERROR(INDEX(Baseline!$G$20:$G$49,MATCH($C8,Baseline!$A$20:$A$49,0)),"RED")) | Q8: =IF($A8="","",$A8&"|"&$B8&"|"&$C8)
D9: =IF($A9="","",IFERROR(INDEX(Baseline!$B$20:$B$49,MATCH($C9,Baseline!$A$20:$A$49,0)),"Line not in baseline")) | E9: =IF($A9="","",IFERROR(INDEX(Baseline!$C$20:$C$49,MATCH($C9,Baseline!$A$20:$A$49,0)),"")) | F9: =IF($A9="","",IFERROR(INDEX(Baseline!$E$20:$E$49,MATCH($C9,Baseline!$A$20:$A$49,0)),"")) | J9: =IF($A9="","",IF($E9="Informational","GREEN",IF($G9="",IF($E9="Mandatory","RED","YELLOW"),IF($N9="Exact",IF(UPPER(TRIM($G9&""))=UPPER(TRIM($F9&"")),"GREEN",$P9),IF(NOT(ISNUMBER($G9)),$P9,IF($N9="Min",IF($G9>=$F9,"GREEN",IF($G9>=$F9-$O9,"YELLOW",$P9)),IF($N9="Max",IF($G9<=$F9,"GREEN",IF($G9<=$F9+$O9,"YELLOW",$P9)),IF($N9="Range",IF(ABS($G9-$F9)<=$O9,"GREEN",$P9),"CHECK RULE")))))))) | K9: =IF($A9="","",IF($H9="Non-Compliant","RED",IF(AND(OR($H9="Alternative Offer",$H9="Partially Compliant"),$J9="GREEN"),"YELLOW",IF(AND($J9="GREEN",ISNUMBER($R9),$R9<Baseline!$B$9),"YELLOW",$J9)))) | L9: =IF($A9="","",IF($K9="GREEN","GREEN",IF(COUNTIFS(Exceptions!$B$5:$B$104,$A9,Exceptions!$C$5:$C$104,$B9,Exceptions!$D$5:$D$104,$C9,Exceptions!$G$5:$G$104,"Accepted",Exceptions!$H$5:$H$104,"<>")>0,"CLEARED",$K9))) | M9: =IF($A9="","",IF($H9="","Declaration missing",IF($H9="Not Stated","Not stated in quotation",IF(AND(ISNUMBER($R9),$R9<Baseline!$B$9),"Low AI confidence - verify",IF(AND($H9="Fully Compliant",$J9<>"GREEN"),"Declared Fully - evidence differs",""))))) | N9: =IF($A9="","",IFERROR(INDEX(Baseline!$D$20:$D$49,MATCH($C9,Baseline!$A$20:$A$49,0)),"")) | O9: =IF($A9="","",IFERROR(INDEX(Baseline!$F$20:$F$49,MATCH($C9,Baseline!$A$20:$A$49,0)),0)) | P9: =IF($A9="","",IFERROR(INDEX(Baseline!$G$20:$G$49,MATCH($C9,Baseline!$A$20:$A$49,0)),"RED")) | Q9: =IF($A9="","",$A9&"|"&$B9&"|"&$C9)
D10: =IF($A10="","",IFERROR(INDEX(Baseline!$B$20:$B$49,MATCH($C10,Baseline!$A$20:$A$49,0)),"Line not in baseline")) | E10: =IF($A10="","",IFERROR(INDEX(Baseline!$C$20:$C$49,MATCH($C10,Baseline!$A$20:$A$49,0)),"")) | F10: =IF($A10="","",IFERROR(INDEX(Baseline!$E$20:$E$49,MATCH($C10,Baseline!$A$20:$A$49,0)),"")) | J10: =IF($A10="","",IF($E10="Informational","GREEN",IF($G10="",IF($E10="Mandatory","RED","YELLOW"),IF($N10="Exact",IF(UPPER(TRIM($G10&""))=UPPER(TRIM($F10&"")),"GREEN",$P10),IF(NOT(ISNUMBER($G10)),$P10,IF($N10="Min",IF($G10>=$F10,"GREEN",IF($G10>=$F10-$O10,"YELLOW",$P10)),IF($N10="Max",IF($G10<=$F10,"GREEN",IF($G10<=$F10+$O10,"YELLOW",$P10)),IF($N10="Range",IF(ABS($G10-$F10)<=$O10,"GREEN",$P10),"CHECK RULE")))))))) | K10: =IF($A10="","",IF($H10="Non-Compliant","RED",IF(AND(OR($H10="Alternative Offer",$H10="Partially Compliant"),$J10="GREEN"),"YELLOW",IF(AND($J10="GREEN",ISNUMBER($R10),$R10<Baseline!$B$9),"YELLOW",$J10)))) | L10: =IF($A10="","",IF($K10="GREEN","GREEN",IF(COUNTIFS(Exceptions!$B$5:$B$104,$A10,Exceptions!$C$5:$C$104,$B10,Exceptions!$D$5:$D$104,$C10,Exceptions!$G$5:$G$104,"Accepted",Exceptions!$H$5:$H$104,"<>")>0,"CLEARED",$K10))) | M10: =IF($A10="","",IF($H10="","Declaration missing",IF($H10="Not Stated","Not stated in quotation",IF(AND(ISNUMBER($R10),$R10<Baseline!$B$9),"Low AI confidence - verify",IF(AND($H10="Fully Compliant",$J10<>"GREEN"),"Declared Fully - evidence differs",""))))) | N10: =IF($A10="","",IFERROR(INDEX(Baseline!$D$20:$D$49,MATCH($C10,Baseline!$A$20:$A$49,0)),"")) | O10: =IF($A10="","",IFERROR(INDEX(Baseline!$F$20:$F$49,MATCH($C10,Baseline!$A$20:$A$49,0)),0)) | P10: =IF($A10="","",IFERROR(INDEX(Baseline!$G$20:$G$49,MATCH($C10,Baseline!$A$20:$A$49,0)),"RED")) | Q10: =IF($A10="","",$A10&"|"&$B10&"|"&$C10)
D11: =IF($A11="","",IFERROR(INDEX(Baseline!$B$20:$B$49,MATCH($C11,Baseline!$A$20:$A$49,0)),"Line not in baseline")) | E11: =IF($A11="","",IFERROR(INDEX(Baseline!$C$20:$C$49,MATCH($C11,Baseline!$A$20:$A$49,0)),"")) | F11: =IF($A11="","",IFERROR(INDEX(Baseline!$E$20:$E$49,MATCH($C11,Baseline!$A$20:$A$49,0)),"")) | J11: =IF($A11="","",IF($E11="Informational","GREEN",IF($G11="",IF($E11="Mandatory","RED","YELLOW"),IF($N11="Exact",IF(UPPER(TRIM($G11&""))=UPPER(TRIM($F11&"")),"GREEN",$P11),IF(NOT(ISNUMBER($G11)),$P11,IF($N11="Min",IF($G11>=$F11,"GREEN",IF($G11>=$F11-$O11,"YELLOW",$P11)),IF($N11="Max",IF($G11<=$F11,"GREEN",IF($G11<=$F11+$O11,"YELLOW",$P11)),IF($N11="Range",IF(ABS($G11-$F11)<=$O11,"GREEN",$P11),"CHECK RULE")))))))) | K11: =IF($A11="","",IF($H11="Non-Compliant","RED",IF(AND(OR($H11="Alternative Offer",$H11="Partially Compliant"),$J11="GREEN"),"YELLOW",IF(AND($J11="GREEN",ISNUMBER($R11),$R11<Baseline!$B$9),"YELLOW",$J11)))) | L11: =IF($A11="","",IF($K11="GREEN","GREEN",IF(COUNTIFS(Exceptions!$B$5:$B$104,$A11,Exceptions!$C$5:$C$104,$B11,Exceptions!$D$5:$D$104,$C11,Exceptions!$G$5:$G$104,"Accepted",Exceptions!$H$5:$H$104,"<>")>0,"CLEARED",$K11))) | M11: =IF($A11="","",IF($H11="","Declaration missing",IF($H11="Not Stated","Not stated in quotation",IF(AND(ISNUMBER($R11),$R11<Baseline!$B$9),"Low AI confidence - verify",IF(AND($H11="Fully Compliant",$J11<>"GREEN"),"Declared Fully - evidence differs",""))))) | N11: =IF($A11="","",IFERROR(INDEX(Baseline!$D$20:$D$49,MATCH($C11,Baseline!$A$20:$A$49,0)),"")) | O11: =IF($A11="","",IFERROR(INDEX(Baseline!$F$20:$F$49,MATCH($C11,Baseline!$A$20:$A$49,0)),0)) | P11: =IF($A11="","",IFERROR(INDEX(Baseline!$G$20:$G$49,MATCH($C11,Baseline!$A$20:$A$49,0)),"RED")) | Q11: =IF($A11="","",$A11&"|"&$B11&"|"&$C11)
D12: =IF($A12="","",IFERROR(INDEX(Baseline!$B$20:$B$49,MATCH($C12,Baseline!$A$20:$A$49,0)),"Line not in baseline")) | E12: =IF($A12="","",IFERROR(INDEX(Baseline!$C$20:$C$49,MATCH($C12,Baseline!$A$20:$A$49,0)),"")) | F12: =IF($A12="","",IFERROR(INDEX(Baseline!$E$20:$E$49,MATCH($C12,Baseline!$A$20:$A$49,0)),"")) | J12: =IF($A12="","",IF($E12="Informational","GREEN",IF($G12="",IF($E12="Mandatory","RED","YELLOW"),IF($N12="Exact",IF(UPPER(TRIM($G12&""))=UPPER(TRIM($F12&"")),"GREEN",$P12),IF(NOT(ISNUMBER($G12)),$P12,IF($N12="Min",IF($G12>=$F12,"GREEN",IF($G12>=$F12-$O12,"YELLOW",$P12)),IF($N12="Max",IF($G12<=$F12,"GREEN",IF($G12<=$F12+$O12,"YELLOW",$P12)),IF($N12="Range",IF(ABS($G12-$F12)<=$O12,"GREEN",$P12),"CHECK RULE")))))))) | K12: =IF($A12="","",IF($H12="Non-Compliant","RED",IF(AND(OR($H12="Alternative Offer",$H12="Partially Compliant"),$J12="GREEN"),"YELLOW",IF(AND($J12="GREEN",ISNUMBER($R12),$R12<Baseline!$B$9),"YELLOW",$J12)))) | L12: =IF($A12="","",IF($K12="GREEN","GREEN",IF(COUNTIFS(Exceptions!$B$5:$B$104,$A12,Exceptions!$C$5:$C$104,$B12,Exceptions!$D$5:$D$104,$C12,Exceptions!$G$5:$G$104,"Accepted",Exceptions!$H$5:$H$104,"<>")>0,"CLEARED",$K12))) | M12: =IF($A12="","",IF($H12="","Declaration missing",IF($H12="Not Stated","Not stated in quotation",IF(AND(ISNUMBER($R12),$R12<Baseline!$B$9),"Low AI confidence - verify",IF(AND($H12="Fully Compliant",$J12<>"GREEN"),"Declared Fully - evidence differs",""))))) | N12: =IF($A12="","",IFERROR(INDEX(Baseline!$D$20:$D$49,MATCH($C12,Baseline!$A$20:$A$49,0)),"")) | O12: =IF($A12="","",IFERROR(INDEX(Baseline!$F$20:$F$49,MATCH($C12,Baseline!$A$20:$A$49,0)),0)) | P12: =IF($A12="","",IFERROR(INDEX(Baseline!$G$20:$G$49,MATCH($C12,Baseline!$A$20:$A$49,0)),"RED")) | Q12: =IF($A12="","",$A12&"|"&$B12&"|"&$C12)
D13: =IF($A13="","",IFERROR(INDEX(Baseline!$B$20:$B$49,MATCH($C13,Baseline!$A$20:$A$49,0)),"Line not in baseline")) | E13: =IF($A13="","",IFERROR(INDEX(Baseline!$C$20:$C$49,MATCH($C13,Baseline!$A$20:$A$49,0)),"")) | F13: =IF($A13="","",IFERROR(INDEX(Baseline!$E$20:$E$49,MATCH($C13,Baseline!$A$20:$A$49,0)),"")) | J13: =IF($A13="","",IF($E13="Informational","GREEN",IF($G13="",IF($E13="Mandatory","RED","YELLOW"),IF($N13="Exact",IF(UPPER(TRIM($G13&""))=UPPER(TRIM($F13&"")),"GREEN",$P13),IF(NOT(ISNUMBER($G13)),$P13,IF($N13="Min",IF($G13>=$F13,"GREEN",IF($G13>=$F13-$O13,"YELLOW",$P13)),IF($N13="Max",IF($G13<=$F13,"GREEN",IF($G13<=$F13+$O13,"YELLOW",$P13)),IF($N13="Range",IF(ABS($G13-$F13)<=$O13,"GREEN",$P13),"CHECK RULE")))))))) | K13: =IF($A13="","",IF($H13="Non-Compliant","RED",IF(AND(OR($H13="Alternative Offer",$H13="Partially Compliant"),$J13="GREEN"),"YELLOW",IF(AND($J13="GREEN",ISNUMBER($R13),$R13<Baseline!$B$9),"YELLOW",$J13)))) | L13: =IF($A13="","",IF($K13="GREEN","GREEN",IF(COUNTIFS(Exceptions!$B$5:$B$104,$A13,Exceptions!$C$5:$C$104,$B13,Exceptions!$D$5:$D$104,$C13,Exceptions!$G$5:$G$104,"Accepted",Exceptions!$H$5:$H$104,"<>")>0,"CLEARED",$K13))) | M13: =IF($A13="","",IF($H13="","Declaration missing",IF($H13="Not Stated","Not stated in quotation",IF(AND(ISNUMBER($R13),$R13<Baseline!$B$9),"Low AI confidence - verify",IF(AND($H13="Fully Compliant",$J13<>"GREEN"),"Declared Fully - evidence differs",""))))) | N13: =IF($A13="","",IFERROR(INDEX(Baseline!$D$20:$D$49,MATCH($C13,Baseline!$A$20:$A$49,0)),"")) | O13: =IF($A13="","",IFERROR(INDEX(Baseline!$F$20:$F$49,MATCH($C13,Baseline!$A$20:$A$49,0)),0)) | P13: =IF($A13="","",IFERROR(INDEX(Baseline!$G$20:$G$49,MATCH($C13,Baseline!$A$20:$A$49,0)),"RED")) | Q13: =IF($A13="","",$A13&"|"&$B13&"|"&$C13)
D14: =IF($A14="","",IFERROR(INDEX(Baseline!$B$20:$B$49,MATCH($C14,Baseline!$A$20:$A$49,0)),"Line not in baseline")) | E14: =IF($A14="","",IFERROR(INDEX(Baseline!$C$20:$C$49,MATCH($C14,Baseline!$A$20:$A$49,0)),"")) | F14: =IF($A14="","",IFERROR(INDEX(Baseline!$E$20:$E$49,MATCH($C14,Baseline!$A$20:$A$49,0)),"")) | J14: =IF($A14="","",IF($E14="Informational","GREEN",IF($G14="",IF($E14="Mandatory","RED","YELLOW"),IF($N14="Exact",IF(UPPER(TRIM($G14&""))=UPPER(TRIM($F14&"")),"GREEN",$P14),IF(NOT(ISNUMBER($G14)),$P14,IF($N14="Min",IF($G14>=$F14,"GREEN",IF($G14>=$F14-$O14,"YELLOW",$P14)),IF($N14="Max",IF($G14<=$F14,"GREEN",IF($G14<=$F14+$O14,"YELLOW",$P14)),IF($N14="Range",IF(ABS($G14-$F14)<=$O14,"GREEN",$P14),"CHECK RULE")))))))) | K14: =IF($A14="","",IF($H14="Non-Compliant","RED",IF(AND(OR($H14="Alternative Offer",$H14="Partially Compliant"),$J14="GREEN"),"YELLOW",IF(AND($J14="GREEN",ISNUMBER($R14),$R14<Baseline!$B$9),"YELLOW",$J14)))) | L14: =IF($A14="","",IF($K14="GREEN","GREEN",IF(COUNTIFS(Exceptions!$B$5:$B$104,$A14,Exceptions!$C$5:$C$104,$B14,Exceptions!$D$5:$D$104,$C14,Exceptions!$G$5:$G$104,"Accepted",Exceptions!$H$5:$H$104,"<>")>0,"CLEARED",$K14))) | M14: =IF($A14="","",IF($H14="","Declaration missing",IF($H14="Not Stated","Not stated in quotation",IF(AND(ISNUMBER($R14),$R14<Baseline!$B$9),"Low AI confidence - verify",IF(AND($H14="Fully Compliant",$J14<>"GREEN"),"Declared Fully - evidence differs",""))))) | N14: =IF($A14="","",IFERROR(INDEX(Baseline!$D$20:$D$49,MATCH($C14,Baseline!$A$20:$A$49,0)),"")) | O14: =IF($A14="","",IFERROR(INDEX(Baseline!$F$20:$F$49,MATCH($C14,Baseline!$A$20:$A$49,0)),0)) | P14: =IF($A14="","",IFERROR(INDEX(Baseline!$G$20:$G$49,MATCH($C14,Baseline!$A$20:$A$49,0)),"RED")) | Q14: =IF($A14="","",$A14&"|"&$B14&"|"&$C14)
D15: =IF($A15="","",IFERROR(INDEX(Baseline!$B$20:$B$49,MATCH($C15,Baseline!$A$20:$A$49,0)),"Line not in baseline")) | E15: =IF($A15="","",IFERROR(INDEX(Baseline!$C$20:$C$49,MATCH($C15,Baseline!$A$20:$A$49,0)),"")) | F15: =IF($A15="","",IFERROR(INDEX(Baseline!$E$20:$E$49,MATCH($C15,Baseline!$A$20:$A$49,0)),"")) | J15: =IF($A15="","",IF($E15="Informational","GREEN",IF($G15="",IF($E15="Mandatory","RED","YELLOW"),IF($N15="Exact",IF(UPPER(TRIM($G15&""))=UPPER(TRIM($F15&"")),"GREEN",$P15),IF(NOT(ISNUMBER($G15)),$P15,IF($N15="Min",IF($G15>=$F15,"GREEN",IF($G15>=$F15-$O15,"YELLOW",$P15)),IF($N15="Max",IF($G15<=$F15,"GREEN",IF($G15<=$F15+$O15,"YELLOW",$P15)),IF($N15="Range",IF(ABS($G15-$F15)<=$O15,"GREEN",$P15),"CHECK RULE")))))))) | K15: =IF($A15="","",IF($H15="Non-Compliant","RED",IF(AND(OR($H15="Alternative Offer",$H15="Partially Compliant"),$J15="GREEN"),"YELLOW",IF(AND($J15="GREEN",ISNUMBER($R15),$R15<Baseline!$B$9),"YELLOW",$J15)))) | L15: =IF($A15="","",IF($K15="GREEN","GREEN",IF(COUNTIFS(Exceptions!$B$5:$B$104,$A15,Exceptions!$C$5:$C$104,$B15,Exceptions!$D$5:$D$104,$C15,Exceptions!$G$5:$G$104,"Accepted",Exceptions!$H$5:$H$104,"<>")>0,"CLEARED",$K15))) | M15: =IF($A15="","",IF($H15="","Declaration missing",IF($H15="Not Stated","Not stated in quotation",IF(AND(ISNUMBER($R15),$R15<Baseline!$B$9),"Low AI confidence - verify",IF(AND($H15="Fully Compliant",$J15<>"GREEN"),"Declared Fully - evidence differs",""))))) | N15: =IF($A15="","",IFERROR(INDEX(Baseline!$D$20:$D$49,MATCH($C15,Baseline!$A$20:$A$49,0)),"")) | O15: =IF($A15="","",IFERROR(INDEX(Baseline!$F$20:$F$49,MATCH($C15,Baseline!$A$20:$A$49,0)),0)) | P15: =IF($A15="","",IFERROR(INDEX(Baseline!$G$20:$G$49,MATCH($C15,Baseline!$A$20:$A$49,0)),"RED")) | Q15: =IF($A15="","",$A15&"|"&$B15&"|"&$C15)
D16: =IF($A16="","",IFERROR(INDEX(Baseline!$B$20:$B$49,MATCH($C16,Baseline!$A$20:$A$49,0)),"Line not in baseline")) | E16: =IF($A16="","",IFERROR(INDEX(Baseline!$C$20:$C$49,MATCH($C16,Baseline!$A$20:$A$49,0)),"")) | F16: =IF($A16="","",IFERROR(INDEX(Baseline!$E$20:$E$49,MATCH($C16,Baseline!$A$20:$A$49,0)),"")) | J16: =IF($A16="","",IF($E16="Informational","GREEN",IF($G16="",IF($E16="Mandatory","RED","YELLOW"),IF($N16="Exact",IF(UPPER(TRIM($G16&""))=UPPER(TRIM($F16&"")),"GREEN",$P16),IF(NOT(ISNUMBER($G16)),$P16,IF($N16="Min",IF($G16>=$F16,"GREEN",IF($G16>=$F16-$O16,"YELLOW",$P16)),IF($N16="Max",IF($G16<=$F16,"GREEN",IF($G16<=$F16+$O16,"YELLOW",$P16)),IF($N16="Range",IF(ABS($G16-$F16)<=$O16,"GREEN",$P16),"CHECK RULE")))))))) | K16: =IF($A16="","",IF($H16="Non-Compliant","RED",IF(AND(OR($H16="Alternative Offer",$H16="Partially Compliant"),$J16="GREEN"),"YELLOW",IF(AND($J16="GREEN",ISNUMBER($R16),$R16<Baseline!$B$9),"YELLOW",$J16)))) | L16: =IF($A16="","",IF($K16="GREEN","GREEN",IF(COUNTIFS(Exceptions!$B$5:$B$104,$A16,Exceptions!$C$5:$C$104,$B16,Exceptions!$D$5:$D$104,$C16,Exceptions!$G$5:$G$104,"Accepted",Exceptions!$H$5:$H$104,"<>")>0,"CLEARED",$K16))) | M16: =IF($A16="","",IF($H16="","Declaration missing",IF($H16="Not Stated","Not stated in quotation",IF(AND(ISNUMBER($R16),$R16<Baseline!$B$9),"Low AI confidence - verify",IF(AND($H16="Fully Compliant",$J16<>"GREEN"),"Declared Fully - evidence differs",""))))) | N16: =IF($A16="","",IFERROR(INDEX(Baseline!$D$20:$D$49,MATCH($C16,Baseline!$A$20:$A$49,0)),"")) | O16: =IF($A16="","",IFERROR(INDEX(Baseline!$F$20:$F$49,MATCH($C16,Baseline!$A$20:$A$49,0)),0)) | P16: =IF($A16="","",IFERROR(INDEX(Baseline!$G$20:$G$49,MATCH($C16,Baseline!$A$20:$A$49,0)),"RED")) | Q16: =IF($A16="","",$A16&"|"&$B16&"|"&$C16)
... D304: =IF($A304="","",IFERROR(INDEX(Baseline!$B$20:$B$49,MATCH($C304,Baseline!$A$20:$A$49,0)),"Line not in baseline")) | E304: =IF($A304="","",IFERROR(INDEX(Baseline!$C$20:$C$49,MATCH($C304,Baseline!$A$20:$A$49,0)),"")) | F304: =IF($A304="","",IFERROR(INDEX(Baseline!$E$20:$E$49,MATCH($C304,Baseline!$A$20:$A$49,0)),"")) | J304: =IF($A304="","",IF($E304="Informational","GREEN",IF($G304="",IF($E304="Mandatory","RED","YELLOW"),IF($N304="Exact",IF(UPPER(TRIM($G304&""))=UPPER(TRIM($F304&"")),"GREEN",$P304),IF(NOT(ISNUMBER($G304)),$P304,IF($N304="Min",IF($G304>=$F304,"GREEN",IF($G304>=$F304-$O304,"YELLOW",$P304)),IF($N304="Max",IF($G304<=$F304,"GREEN",IF($G304<=$F304+$O304,"YELLOW",$P304)),IF($N304="Range",IF(ABS($G304-$F304)<=$O304,"GREEN",$P304),"CHECK RULE")))))))) | K304: =IF($A304="","",IF($H304="Non-Compliant","RED",IF(AND(OR($H304="Alternative Offer",$H304="Partially Compliant"),$J304="GREEN"),"YELLOW",IF(AND($J304="GREEN",ISNUMBER($R304),$R304<Baseline!$B$9),"YELLOW",$J304)))) | L304: =IF($A304="","",IF($K304="GREEN","GREEN",IF(COUNTIFS(Exceptions!$B$5:$B$104,$A304,Exceptions!$C$5:$C$104,$B304,Exceptions!$D$5:$D$104,$C304,Exceptions!$G$5:$G$104,"Accepted",Exceptions!$H$5:$H$104,"<>")>0,"CLEARED",$K304))) | M304: =IF($A304="","",IF($H304="","Declaration missing",IF($H304="Not Stated","Not stated in quotation",IF(AND(ISNUMBER($R304),$R304<Baseline!$B$9),"Low AI confidence - verify",IF(AND($H304="Fully Compliant",$J304<>"GREEN"),"Declared Fully - evidence differs",""))))) | N304: =IF($A304="","",IFERROR(INDEX(Baseline!$D$20:$D$49,MATCH($C304,Baseline!$A$20:$A$49,0)),"")) | O304: =IF($A304="","",IFERROR(INDEX(Baseline!$F$20:$F$49,MATCH($C304,Baseline!$A$20:$A$49,0)),0)) | P304: =IF($A304="","",IFERROR(INDEX(Baseline!$G$20:$G$49,MATCH($C304,Baseline!$A$20:$A$49,0)),"RED")) | Q304: =IF($A304="","",$A304&"|"&$B304&"|"&$C304)

Sheet Exceptions
A1: Deviation & Exception Register
A2: Only Decision = Accepted with an Approver clears a line on Submissions. None logged yet.
A4: Ref | B4: Supplier | C4: Rev | D4: Line | E4: Parameter | F4: Deviation (required vs offered) | G4: Decision | H4: Approver | I4: Date | J4: Justification
E5: =IF($D5="","",IFERROR(INDEX(Baseline!$B$20:$B$49,MATCH($D5,Baseline!$A$20:$A$49,0)),""))
E6: =IF($D6="","",IFERROR(INDEX(Baseline!$B$20:$B$49,MATCH($D6,Baseline!$A$20:$A$49,0)),""))
E7: =IF($D7="","",IFERROR(INDEX(Baseline!$B$20:$B$49,MATCH($D7,Baseline!$A$20:$A$49,0)),""))
E8: =IF($D8="","",IFERROR(INDEX(Baseline!$B$20:$B$49,MATCH($D8,Baseline!$A$20:$A$49,0)),""))
E9: =IF($D9="","",IFERROR(INDEX(Baseline!$B$20:$B$49,MATCH($D9,Baseline!$A$20:$A$49,0)),""))
E10: =IF($D10="","",IFERROR(INDEX(Baseline!$B$20:$B$49,MATCH($D10,Baseline!$A$20:$A$49,0)),""))
E11: =IF($D11="","",IFERROR(INDEX(Baseline!$B$20:$B$49,MATCH($D11,Baseline!$A$20:$A$49,0)),""))
E12: =IF($D12="","",IFERROR(INDEX(Baseline!$B$20:$B$49,MATCH($D12,Baseline!$A$20:$A$49,0)),""))
E13: =IF($D13="","",IFERROR(INDEX(Baseline!$B$20:$B$49,MATCH($D13,Baseline!$A$20:$A$49,0)),""))
E14: =IF($D14="","",IFERROR(INDEX(Baseline!$B$20:$B$49,MATCH($D14,Baseline!$A$20:$A$49,0)),""))
E15: =IF($D15="","",IFERROR(INDEX(Baseline!$B$20:$B$49,MATCH($D15,Baseline!$A$20:$A$49,0)),""))
E16: =IF($D16="","",IFERROR(INDEX(Baseline!$B$20:$B$49,MATCH($D16,Baseline!$A$20:$A$49,0)),""))
... E104: =IF($D104="","",IFERROR(INDEX(Baseline!$B$20:$B$49,MATCH($D104,Baseline!$A$20:$A$49,0)),""))

Sheet Clarifications
A1: Clarification Log
A2: Drafts only. Review and send before changing status.
A3: Ref | B3: Date raised | C3: Supplier | D3: Line(s) | E3: Issue | F3: Sent by | G3: Due date | H3: Response date | I3: Resulting rev | J3: Status
A4: CL-001 | B4: 46296 | C4: Tilal Al-Eamar | D4: 5, 19-24 | E4: Quote dated 16-Aug-2026, before the RFQ. Confirm prices valid; provide skylight spec (structure, glass), door glass, validity, warranty. | J4: Draft
A5: CL-002 | B5: 46296 | C5: Lamset Ebdaa | D5: 4, 13, 17-24 | E5: Glass thickness, door and skylight specs, validity and warranty not stated. | J5: Draft
A6: CL-003 | B6: 46296 | C6: Falcon | D6: 4, 20 | E6: Offer expired 30-Sep. Skylight profile 2.5 mm vs 3 mm minimum: confirm revised spec and price. | J6: Draft
A7: CL-004 | B7: 46296 | C7: Mishkal | D7: 13, 19, 21 | E7: Windows glass 6/8/6 = 20 mm vs 24 mm. Doors stated 24 mm but 6/10/6 = 22 mm. Skylight stated 28 mm but 6+16+8 = 30 mm. Requote to 6+12+6. | J7: Draft
A8: CL-005 | B8: 46296 | C8: Qimam | D8: 4, 14, 24 | E8: Offer expired 27-Sep. Confirm tempering and 10-year skylight warranty (5 quoted). | J8: Draft
A9: CL-006 | B9: 46296 | C9: Al Shareef | D9: 1-3 | E9: Quote built on own BOQ. No skylight item (curtain wall priced instead); doors priced as hinged windows. Requote on RFQ BOQ. | J9: Draft
A10: CL-007 | B10: 46296 | C10: Ultra Frame | D10: 2, 19 | E10: Doors quoted 27 m2 vs RFQ 23 m2. Door glass stated 24 mm but 6+16+6 = 28 mm. | J10: Draft

Sheet Compliance Matrix
A1: Compliance Matrix (latest revision per supplier)
D4: Supplier
D5: Latest revision | E5: =IF(E4="","",IF(COUNTIF(Submissions!$A$5:$A$304,E4)=0,"",SUMPRODUCT(MAX((Submissions!$A$5:$A$304=E4)*Submissions!$B$5:$B$304)))) | F5: =IF(F4="","",IF(COUNTIF(Submissions!$A$5:$A$304,F4)=0,"",SUMPRODUCT(MAX((Submissions!$A$5:$A$304=F4)*Submissions!$B$5:$B$304)))) | G5: =IF(G4="","",IF(COUNTIF(Submissions!$A$5:$A$304,G4)=0,"",SUMPRODUCT(MAX((Submissions!$A$5:$A$304=G4)*Submissions!$B$5:$B$304)))) | H5: =IF(H4="","",IF(COUNTIF(Submissions!$A$5:$A$304,H4)=0,"",SUMPRODUCT(MAX((Submissions!$A$5:$A$304=H4)*Submissions!$B$5:$B$304)))) | I5: =IF(I4="","",IF(COUNTIF(Submissions!$A$5:$A$304,I4)=0,"",SUMPRODUCT(MAX((Submissions!$A$5:$A$304=I4)*Submissions!$B$5:$B$304)))) | J5: =IF(J4="","",IF(COUNTIF(Submissions!$A$5:$A$304,J4)=0,"",SUMPRODUCT(MAX((Submissions!$A$5:$A$304=J4)*Submissions!$B$5:$B$304)))) | K5: =IF(K4="","",IF(COUNTIF(Submissions!$A$5:$A$304,K4)=0,"",SUMPRODUCT(MAX((Submissions!$A$5:$A$304=K4)*Submissions!$B$5:$B$304)))) | L5: =IF(L4="","",IF(COUNTIF(Submissions!$A$5:$A$304,L4)=0,"",SUMPRODUCT(MAX((Submissions!$A$5:$A$304=L4)*Submissions!$B$5:$B$304)))) | ... N5: =IF(N4="","",IF(COUNTIF(Submissions!$A$5:$A$304,N4)=0,"",SUMPRODUCT(MAX((Submissions!$A$5:$A$304=N4)*Submissions!$B$5:$B$304))))
A6: Line | B6: Parameter | C6: Class | D6: Required | E6: Status | F6: Status | G6: Status | H6: Status | I6: Status | J6: Status | K6: Status | L6: Status | M6: Status | N6: Status
A7: =IF(Baseline!A20="","",Baseline!A20) | B7: =IF($A7="","",Baseline!B20) | C7: =IF($A7="","",Baseline!C20) | D7: =IF($A7="","",IF(Baseline!E20="","",Baseline!E20)) | E7: =IF(OR($A7="",E$4=""),"",IFERROR(INDEX(Submissions!$L$5:$L$304,MATCH(E$4&"|"&E$5&"|"&$A7,Submissions!$Q$5:$Q$304,0)),"NO DATA")) | F7: =IF(OR($A7="",F$4=""),"",IFERROR(INDEX(Submissions!$L$5:$L$304,MATCH(F$4&"|"&F$5&"|"&$A7,Submissions!$Q$5:$Q$304,0)),"NO DATA")) | G7: =IF(OR($A7="",G$4=""),"",IFERROR(INDEX(Submissions!$L$5:$L$304,MATCH(G$4&"|"&G$5&"|"&$A7,Submissions!$Q$5:$Q$304,0)),"NO DATA")) | H7: =IF(OR($A7="",H$4=""),"",IFERROR(INDEX(Submissions!$L$5:$L$304,MATCH(H$4&"|"&H$5&"|"&$A7,Submissions!$Q$5:$Q$304,0)),"NO DATA")) | I7: =IF(OR($A7="",I$4=""),"",IFERROR(INDEX(Submissions!$L$5:$L$304,MATCH(I$4&"|"&I$5&"|"&$A7,Submissions!$Q$5:$Q$304,0)),"NO DATA")) | J7: =IF(OR($A7="",J$4=""),"",IFERROR(INDEX(Submissions!$L$5:$L$304,MATCH(J$4&"|"&J$5&"|"&$A7,Submissions!$Q$5:$Q$304,0)),"NO DATA")) | K7: =IF(OR($A7="",K$4=""),"",IFERROR(INDEX(Submissions!$L$5:$L$304,MATCH(K$4&"|"&K$5&"|"&$A7,Submissions!$Q$5:$Q$304,0)),"NO DATA")) | L7: =IF(OR($A7="",L$4=""),"",IFERROR(INDEX(Submissions!$L$5:$L$304,MATCH(L$4&"|"&L$5&"|"&$A7,Submissions!$Q$5:$Q$304,0)),"NO DATA")) | ... N7: =IF(OR($A7="",N$4=""),"",IFERROR(INDEX(Submissions!$L$5:$L$304,MATCH(N$4&"|"&N$5&"|"&$A7,Submissions!$Q$5:$Q$304,0)),"NO DATA"))
A8: =IF(Baseline!A21="","",Baseline!A21) | B8: =IF($A8="","",Baseline!B21) | C8: =IF($A8="","",Baseline!C21) | D8: =IF($A8="","",IF(Baseline!E21="","",Baseline!E21)) | E8: =IF(OR($A8="",E$4=""),"",IFERROR(INDEX(Submissions!$L$5:$L$304,MATCH(E$4&"|"&E$5&"|"&$A8,Submissions!$Q$5:$Q$304,0)),"NO DATA")) | F8: =IF(OR($A8="",F$4=""),"",IFERROR(INDEX(Submissions!$L$5:$L$304,MATCH(F$4&"|"&F$5&"|"&$A8,Submissions!$Q$5:$Q$304,0)),"NO DATA")) | G8: =IF(OR($A8="",G$4=""),"",IFERROR(INDEX(Submissions!$L$5:$L$304,MATCH(G$4&"|"&G$5&"|"&$A8,Submissions!$Q$5:$Q$304,0)),"NO DATA")) | H8: =IF(OR($A8="",H$4=""),"",IFERROR(INDEX(Submissions!$L$5:$L$304,MATCH(H$4&"|"&H$5&"|"&$A8,Submissions!$Q$5:$Q$304,0)),"NO DATA")) | I8: =IF(OR($A8="",I$4=""),"",IFERROR(INDEX(Submissions!$L$5:$L$304,MATCH(I$4&"|"&I$5&"|"&$A8,Submissions!$Q$5:$Q$304,0)),"NO DATA")) | J8: =IF(OR($A8="",J$4=""),"",IFERROR(INDEX(Submissions!$L$5:$L$304,MATCH(J$4&"|"&J$5&"|"&$A8,Submissions!$Q$5:$Q$304,0)),"NO DATA")) | K8: =IF(OR($A8="",K$4=""),"",IFERROR(INDEX(Submissions!$L$5:$L$304,MATCH(K$4&"|"&K$5&"|"&$A8,Submissions!$Q$5:$Q$304,0)),"NO DATA")) | L8: =IF(OR($A8="",L$4=""),"",IFERROR(INDEX(Submissions!$L$5:$L$304,MATCH(L$4&"|"&L$5&"|"&$A8,Submissions!$Q$5:$Q$304,0)),"NO DATA")) | ... N8: =IF(OR($A8="",N$4=""),"",IFERROR(INDEX(Submissions!$L$5:$L$304,MATCH(N$4&"|"&N$5&"|"&$A8,Submissions!$Q$5:$Q$304,0)),"NO DATA"))
A9: =IF(Baseline!A22="","",Baseline!A22) | B9: =IF($A9="","",Baseline!B22) | C9: =IF($A9="","",Baseline!C22) | D9: =IF($A9="","",IF(Baseline!E22="","",Baseline!E22)) | E9: =IF(OR($A9="",E$4=""),"",IFERROR(INDEX(Submissions!$L$5:$L$304,MATCH(E$4&"|"&E$5&"|"&$A9,Submissions!$Q$5:$Q$304,0)),"NO DATA")) | F9: =IF(OR($A9="",F$4=""),"",IFERROR(INDEX(Submissions!$L$5:$L$304,MATCH(F$4&"|"&F$5&"|"&$A9,Submissions!$Q$5:$Q$304,0)),"NO DATA")) | G9: =IF(OR($A9="",G$4=""),"",IFERROR(INDEX(Submissions!$L$5:$L$304,MATCH(G$4&"|"&G$5&"|"&$A9,Submissions!$Q$5:$Q$304,0)),"NO DATA")) | H9: =IF(OR($A9="",H$4=""),"",IFERROR(INDEX(Submissions!$L$5:$L$304,MATCH(H$4&"|"&H$5&"|"&$A9,Submissions!$Q$5:$Q$304,0)),"NO DATA")) | I9: =IF(OR($A9="",I$4=""),"",IFERROR(INDEX(Submissions!$L$5:$L$304,MATCH(I$4&"|"&I$5&"|"&$A9,Submissions!$Q$5:$Q$304,0)),"NO DATA")) | J9: =IF(OR($A9="",J$4=""),"",IFERROR(INDEX(Submissions!$L$5:$L$304,MATCH(J$4&"|"&J$5&"|"&$A9,Submissions!$Q$5:$Q$304,0)),"NO DATA")) | K9: =IF(OR($A9="",K$4=""),"",IFERROR(INDEX(Submissions!$L$5:$L$304,MATCH(K$4&"|"&K$5&"|"&$A9,Submissions!$Q$5:$Q$304,0)),"NO DATA")) | L9: =IF(OR($A9="",L$4=""),"",IFERROR(INDEX(Submissions!$L$5:$L$304,MATCH(L$4&"|"&L$5&"|"&$A9,Submissions!$Q$5:$Q$304,0)),"NO DATA")) | ... N9: =IF(OR($A9="",N$4=""),"",IFERROR(INDEX(Submissions!$L$5:$L$304,MATCH(N$4&"|"&N$5&"|"&$A9,Submissions!$Q$5:$Q$304,0)),"NO DATA"))
A10: =IF(Baseline!A23="","",Baseline!A23) | B10: =IF($A10="","",Baseline!B23) | C10: =IF($A10="","",Baseline!C23) | D10: =IF($A10="","",IF(Baseline!E23="","",Baseline!E23)) | E10: =IF(OR($A10="",E$4=""),"",IFERROR(INDEX(Submissions!$L$5:$L$304,MATCH(E$4&"|"&E$5&"|"&$A10,Submissions!$Q$5:$Q$304,0)),"NO DATA")) | F10: =IF(OR($A10="",F$4=""),"",IFERROR(INDEX(Submissions!$L$5:$L$304,MATCH(F$4&"|"&F$5&"|"&$A10,Submissions!$Q$5:$Q$304,0)),"NO DATA")) | G10: =IF(OR($A10="",G$4=""),"",IFERROR(INDEX(Submissions!$L$5:$L$304,MATCH(G$4&"|"&G$5&"|"&$A10,Submissions!$Q$5:$Q$304,0)),"NO DATA")) | H10: =IF(OR($A10="",H$4=""),"",IFERROR(INDEX(Submissions!$L$5:$L$304,MATCH(H$4&"|"&H$5&"|"&$A10,Submissions!$Q$5:$Q$304,0)),"NO DATA")) | I10: =IF(OR($A10="",I$4=""),"",IFERROR(INDEX(Submissions!$L$5:$L$304,MATCH(I$4&"|"&I$5&"|"&$A10,Submissions!$Q$5:$Q$304,0)),"NO DATA")) | J10: =IF(OR($A10="",J$4=""),"",IFERROR(INDEX(Submissions!$L$5:$L$304,MATCH(J$4&"|"&J$5&"|"&$A10,Submissions!$Q$5:$Q$304,0)),"NO DATA")) | K10: =IF(OR($A10="",K$4=""),"",IFERROR(INDEX(Submissions!$L$5:$L$304,MATCH(K$4&"|"&K$5&"|"&$A10,Submissions!$Q$5:$Q$304,0)),"NO DATA")) | L10: =IF(OR($A10="",L$4=""),"",IFERROR(INDEX(Submissions!$L$5:$L$304,MATCH(L$4&"|"&L$5&"|"&$A10,Submissions!$Q$5:$Q$304,0)),"NO DATA")) | ... N10: =IF(OR($A10="",N$4=""),"",IFERROR(INDEX(Submissions!$L$5:$L$304,MATCH(N$4&"|"&N$5&"|"&$A10,Submissions!$Q$5:$Q$304,0)),"NO DATA"))
A11: =IF(Baseline!A24="","",Baseline!A24) | B11: =IF($A11="","",Baseline!B24) | C11: =IF($A11="","",Baseline!C24) | D11: =IF($A11="","",IF(Baseline!E24="","",Baseline!E24)) | E11: =IF(OR($A11="",E$4=""),"",IFERROR(INDEX(Submissions!$L$5:$L$304,MATCH(E$4&"|"&E$5&"|"&$A11,Submissions!$Q$5:$Q$304,0)),"NO DATA")) | F11: =IF(OR($A11="",F$4=""),"",IFERROR(INDEX(Submissions!$L$5:$L$304,MATCH(F$4&"|"&F$5&"|"&$A11,Submissions!$Q$5:$Q$304,0)),"NO DATA")) | G11: =IF(OR($A11="",G$4=""),"",IFERROR(INDEX(Submissions!$L$5:$L$304,MATCH(G$4&"|"&G$5&"|"&$A11,Submissions!$Q$5:$Q$304,0)),"NO DATA")) | H11: =IF(OR($A11="",H$4=""),"",IFERROR(INDEX(Submissions!$L$5:$L$304,MATCH(H$4&"|"&H$5&"|"&$A11,Submissions!$Q$5:$Q$304,0)),"NO DATA")) | I11: =IF(OR($A11="",I$4=""),"",IFERROR(INDEX(Submissions!$L$5:$L$304,MATCH(I$4&"|"&I$5&"|"&$A11,Submissions!$Q$5:$Q$304,0)),"NO DATA")) | J11: =IF(OR($A11="",J$4=""),"",IFERROR(INDEX(Submissions!$L$5:$L$304,MATCH(J$4&"|"&J$5&"|"&$A11,Submissions!$Q$5:$Q$304,0)),"NO DATA")) | K11: =IF(OR($A11="",K$4=""),"",IFERROR(INDEX(Submissions!$L$5:$L$304,MATCH(K$4&"|"&K$5&"|"&$A11,Submissions!$Q$5:$Q$304,0)),"NO DATA")) | L11: =IF(OR($A11="",L$4=""),"",IFERROR(INDEX(Submissions!$L$5:$L$304,MATCH(L$4&"|"&L$5&"|"&$A11,Submissions!$Q$5:$Q$304,0)),"NO DATA")) | ... N11: =IF(OR($A11="",N$4=""),"",IFERROR(INDEX(Submissions!$L$5:$L$304,MATCH(N$4&"|"&N$5&"|"&$A11,Submissions!$Q$5:$Q$304,0)),"NO DATA"))
A12: =IF(Baseline!A25="","",Baseline!A25) | B12: =IF($A12="","",Baseline!B25) | C12: =IF($A12="","",Baseline!C25) | D12: =IF($A12="","",IF(Baseline!E25="","",Baseline!E25)) | E12: =IF(OR($A12="",E$4=""),"",IFERROR(INDEX(Submissions!$L$5:$L$304,MATCH(E$4&"|"&E$5&"|"&$A12,Submissions!$Q$5:$Q$304,0)),"NO DATA")) | F12: =IF(OR($A12="",F$4=""),"",IFERROR(INDEX(Submissions!$L$5:$L$304,MATCH(F$4&"|"&F$5&"|"&$A12,Submissions!$Q$5:$Q$304,0)),"NO DATA")) | G12: =IF(OR($A12="",G$4=""),"",IFERROR(INDEX(Submissions!$L$5:$L$304,MATCH(G$4&"|"&G$5&"|"&$A12,Submissions!$Q$5:$Q$304,0)),"NO DATA")) | H12: =IF(OR($A12="",H$4=""),"",IFERROR(INDEX(Submissions!$L$5:$L$304,MATCH(H$4&"|"&H$5&"|"&$A12,Submissions!$Q$5:$Q$304,0)),"NO DATA")) | I12: =IF(OR($A12="",I$4=""),"",IFERROR(INDEX(Submissions!$L$5:$L$304,MATCH(I$4&"|"&I$5&"|"&$A12,Submissions!$Q$5:$Q$304,0)),"NO DATA")) | J12: =IF(OR($A12="",J$4=""),"",IFERROR(INDEX(Submissions!$L$5:$L$304,MATCH(J$4&"|"&J$5&"|"&$A12,Submissions!$Q$5:$Q$304,0)),"NO DATA")) | K12: =IF(OR($A12="",K$4=""),"",IFERROR(INDEX(Submissions!$L$5:$L$304,MATCH(K$4&"|"&K$5&"|"&$A12,Submissions!$Q$5:$Q$304,0)),"NO DATA")) | L12: =IF(OR($A12="",L$4=""),"",IFERROR(INDEX(Submissions!$L$5:$L$304,MATCH(L$4&"|"&L$5&"|"&$A12,Submissions!$Q$5:$Q$304,0)),"NO DATA")) | ... N12: =IF(OR($A12="",N$4=""),"",IFERROR(INDEX(Submissions!$L$5:$L$304,MATCH(N$4&"|"&N$5&"|"&$A12,Submissions!$Q$5:$Q$304,0)),"NO DATA"))
A13: =IF(Baseline!A26="","",Baseline!A26) | B13: =IF($A13="","",Baseline!B26) | C13: =IF($A13="","",Baseline!C26) | D13: =IF($A13="","",IF(Baseline!E26="","",Baseline!E26)) | E13: =IF(OR($A13="",E$4=""),"",IFERROR(INDEX(Submissions!$L$5:$L$304,MATCH(E$4&"|"&E$5&"|"&$A13,Submissions!$Q$5:$Q$304,0)),"NO DATA")) | F13: =IF(OR($A13="",F$4=""),"",IFERROR(INDEX(Submissions!$L$5:$L$304,MATCH(F$4&"|"&F$5&"|"&$A13,Submissions!$Q$5:$Q$304,0)),"NO DATA")) | G13: =IF(OR($A13="",G$4=""),"",IFERROR(INDEX(Submissions!$L$5:$L$304,MATCH(G$4&"|"&G$5&"|"&$A13,Submissions!$Q$5:$Q$304,0)),"NO DATA")) | H13: =IF(OR($A13="",H$4=""),"",IFERROR(INDEX(Submissions!$L$5:$L$304,MATCH(H$4&"|"&H$5&"|"&$A13,Submissions!$Q$5:$Q$304,0)),"NO DATA")) | I13: =IF(OR($A13="",I$4=""),"",IFERROR(INDEX(Submissions!$L$5:$L$304,MATCH(I$4&"|"&I$5&"|"&$A13,Submissions!$Q$5:$Q$304,0)),"NO DATA")) | J13: =IF(OR($A13="",J$4=""),"",IFERROR(INDEX(Submissions!$L$5:$L$304,MATCH(J$4&"|"&J$5&"|"&$A13,Submissions!$Q$5:$Q$304,0)),"NO DATA")) | K13: =IF(OR($A13="",K$4=""),"",IFERROR(INDEX(Submissions!$L$5:$L$304,MATCH(K$4&"|"&K$5&"|"&$A13,Submissions!$Q$5:$Q$304,0)),"NO DATA")) | L13: =IF(OR($A13="",L$4=""),"",IFERROR(INDEX(Submissions!$L$5:$L$304,MATCH(L$4&"|"&L$5&"|"&$A13,Submissions!$Q$5:$Q$304,0)),"NO DATA")) | ... N13: =IF(OR($A13="",N$4=""),"",IFERROR(INDEX(Submissions!$L$5:$L$304,MATCH(N$4&"|"&N$5&"|"&$A13,Submissions!$Q$5:$Q$304,0)),"NO DATA"))
A14: =IF(Baseline!A27="","",Baseline!A27) | B14: =IF($A14="","",Baseline!B27) | C14: =IF($A14="","",Baseline!C27) | D14: =IF($A14="","",IF(Baseline!E27="","",Baseline!E27)) | E14: =IF(OR($A14="",E$4=""),"",IFERROR(INDEX(Submissions!$L$5:$L$304,MATCH(E$4&"|"&E$5&"|"&$A14,Submissions!$Q$5:$Q$304,0)),"NO DATA")) | F14: =IF(OR($A14="",F$4=""),"",IFERROR(INDEX(Submissions!$L$5:$L$304,MATCH(F$4&"|"&F$5&"|"&$A14,Submissions!$Q$5:$Q$304,0)),"NO DATA")) | G14: =IF(OR($A14="",G$4=""),"",IFERROR(INDEX(Submissions!$L$5:$L$304,MATCH(G$4&"|"&G$5&"|"&$A14,Submissions!$Q$5:$Q$304,0)),"NO DATA")) | H14: =IF(OR($A14="",H$4=""),"",IFERROR(INDEX(Submissions!$L$5:$L$304,MATCH(H$4&"|"&H$5&"|"&$A14,Submissions!$Q$5:$Q$304,0)),"NO DATA")) | I14: =IF(OR($A14="",I$4=""),"",IFERROR(INDEX(Submissions!$L$5:$L$304,MATCH(I$4&"|"&I$5&"|"&$A14,Submissions!$Q$5:$Q$304,0)),"NO DATA")) | J14: =IF(OR($A14="",J$4=""),"",IFERROR(INDEX(Submissions!$L$5:$L$304,MATCH(J$4&"|"&J$5&"|"&$A14,Submissions!$Q$5:$Q$304,0)),"NO DATA")) | K14: =IF(OR($A14="",K$4=""),"",IFERROR(INDEX(Submissions!$L$5:$L$304,MATCH(K$4&"|"&K$5&"|"&$A14,Submissions!$Q$5:$Q$304,0)),"NO DATA")) | L14: =IF(OR($A14="",L$4=""),"",IFERROR(INDEX(Submissions!$L$5:$L$304,MATCH(L$4&"|"&L$5&"|"&$A14,Submissions!$Q$5:$Q$304,0)),"NO DATA")) | ... N14: =IF(OR($A14="",N$4=""),"",IFERROR(INDEX(Submissions!$L$5:$L$304,MATCH(N$4&"|"&N$5&"|"&$A14,Submissions!$Q$5:$Q$304,0)),"NO DATA"))
A15: =IF(Baseline!A28="","",Baseline!A28) | B15: =IF($A15="","",Baseline!B28) | C15: =IF($A15="","",Baseline!C28) | D15: =IF($A15="","",IF(Baseline!E28="","",Baseline!E28)) | E15: =IF(OR($A15="",E$4=""),"",IFERROR(INDEX(Submissions!$L$5:$L$304,MATCH(E$4&"|"&E$5&"|"&$A15,Submissions!$Q$5:$Q$304,0)),"NO DATA")) | F15: =IF(OR($A15="",F$4=""),"",IFERROR(INDEX(Submissions!$L$5:$L$304,MATCH(F$4&"|"&F$5&"|"&$A15,Submissions!$Q$5:$Q$304,0)),"NO DATA")) | G15: =IF(OR($A15="",G$4=""),"",IFERROR(INDEX(Submissions!$L$5:$L$304,MATCH(G$4&"|"&G$5&"|"&$A15,Submissions!$Q$5:$Q$304,0)),"NO DATA")) | H15: =IF(OR($A15="",H$4=""),"",IFERROR(INDEX(Submissions!$L$5:$L$304,MATCH(H$4&"|"&H$5&"|"&$A15,Submissions!$Q$5:$Q$304,0)),"NO DATA")) | I15: =IF(OR($A15="",I$4=""),"",IFERROR(INDEX(Submissions!$L$5:$L$304,MATCH(I$4&"|"&I$5&"|"&$A15,Submissions!$Q$5:$Q$304,0)),"NO DATA")) | J15: =IF(OR($A15="",J$4=""),"",IFERROR(INDEX(Submissions!$L$5:$L$304,MATCH(J$4&"|"&J$5&"|"&$A15,Submissions!$Q$5:$Q$304,0)),"NO DATA")) | K15: =IF(OR($A15="",K$4=""),"",IFERROR(INDEX(Submissions!$L$5:$L$304,MATCH(K$4&"|"&K$5&"|"&$A15,Submissions!$Q$5:$Q$304,0)),"NO DATA")) | L15: =IF(OR($A15="",L$4=""),"",IFERROR(INDEX(Submissions!$L$5:$L$304,MATCH(L$4&"|"&L$5&"|"&$A15,Submissions!$Q$5:$Q$304,0)),"NO DATA")) | ... N15: =IF(OR($A15="",N$4=""),"",IFERROR(INDEX(Submissions!$L$5:$L$304,MATCH(N$4&"|"&N$5&"|"&$A15,Submissions!$Q$5:$Q$304,0)),"NO DATA"))
A16: =IF(Baseline!A29="","",Baseline!A29) | B16: =IF($A16="","",Baseline!B29) | C16: =IF($A16="","",Baseline!C29) | D16: =IF($A16="","",IF(Baseline!E29="","",Baseline!E29)) | E16: =IF(OR($A16="",E$4=""),"",IFERROR(INDEX(Submissions!$L$5:$L$304,MATCH(E$4&"|"&E$5&"|"&$A16,Submissions!$Q$5:$Q$304,0)),"NO DATA")) | F16: =IF(OR($A16="",F$4=""),"",IFERROR(INDEX(Submissions!$L$5:$L$304,MATCH(F$4&"|"&F$5&"|"&$A16,Submissions!$Q$5:$Q$304,0)),"NO DATA")) | G16: =IF(OR($A16="",G$4=""),"",IFERROR(INDEX(Submissions!$L$5:$L$304,MATCH(G$4&"|"&G$5&"|"&$A16,Submissions!$Q$5:$Q$304,0)),"NO DATA")) | H16: =IF(OR($A16="",H$4=""),"",IFERROR(INDEX(Submissions!$L$5:$L$304,MATCH(H$4&"|"&H$5&"|"&$A16,Submissions!$Q$5:$Q$304,0)),"NO DATA")) | I16: =IF(OR($A16="",I$4=""),"",IFERROR(INDEX(Submissions!$L$5:$L$304,MATCH(I$4&"|"&I$5&"|"&$A16,Submissions!$Q$5:$Q$304,0)),"NO DATA")) | J16: =IF(OR($A16="",J$4=""),"",IFERROR(INDEX(Submissions!$L$5:$L$304,MATCH(J$4&"|"&J$5&"|"&$A16,Submissions!$Q$5:$Q$304,0)),"NO DATA")) | K16: =IF(OR($A16="",K$4=""),"",IFERROR(INDEX(Submissions!$L$5:$L$304,MATCH(K$4&"|"&K$5&"|"&$A16,Submissions!$Q$5:$Q$304,0)),"NO DATA")) | L16: =IF(OR($A16="",L$4=""),"",IFERROR(INDEX(Submissions!$L$5:$L$304,MATCH(L$4&"|"&L$5&"|"&$A16,Submissions!$Q$5:$Q$304,0)),"NO DATA")) | ... N16: =IF(OR($A16="",N$4=""),"",IFERROR(INDEX(Submissions!$L$5:$L$304,MATCH(N$4&"|"&N$5&"|"&$A16,Submissions!$Q$5:$Q$304,0)),"NO DATA"))
A17: =IF(Baseline!A30="","",Baseline!A30) | B17: =IF($A17="","",Baseline!B30) | C17: =IF($A17="","",Baseline!C30) | D17: =IF($A17="","",IF(Baseline!E30="","",Baseline!E30)) | E17: =IF(OR($A17="",E$4=""),"",IFERROR(INDEX(Submissions!$L$5:$L$304,MATCH(E$4&"|"&E$5&"|"&$A17,Submissions!$Q$5:$Q$304,0)),"NO DATA")) | F17: =IF(OR($A17="",F$4=""),"",IFERROR(INDEX(Submissions!$L$5:$L$304,MATCH(F$4&"|"&F$5&"|"&$A17,Submissions!$Q$5:$Q$304,0)),"NO DATA")) | G17: =IF(OR($A17="",G$4=""),"",IFERROR(INDEX(Submissions!$L$5:$L$304,MATCH(G$4&"|"&G$5&"|"&$A17,Submissions!$Q$5:$Q$304,0)),"NO DATA")) | H17: =IF(OR($A17="",H$4=""),"",IFERROR(INDEX(Submissions!$L$5:$L$304,MATCH(H$4&"|"&H$5&"|"&$A17,Submissions!$Q$5:$Q$304,0)),"NO DATA")) | I17: =IF(OR($A17="",I$4=""),"",IFERROR(INDEX(Submissions!$L$5:$L$304,MATCH(I$4&"|"&I$5&"|"&$A17,Submissions!$Q$5:$Q$304,0)),"NO DATA")) | J17: =IF(OR($A17="",J$4=""),"",IFERROR(INDEX(Submissions!$L$5:$L$304,MATCH(J$4&"|"&J$5&"|"&$A17,Submissions!$Q$5:$Q$304,0)),"NO DATA")) | K17: =IF(OR($A17="",K$4=""),"",IFERROR(INDEX(Submissions!$L$5:$L$304,MATCH(K$4&"|"&K$5&"|"&$A17,Submissions!$Q$5:$Q$304,0)),"NO DATA")) | L17: =IF(OR($A17="",L$4=""),"",IFERROR(INDEX(Submissions!$L$5:$L$304,MATCH(L$4&"|"&L$5&"|"&$A17,Submissions!$Q$5:$Q$304,0)),"NO DATA")) | ... N17: =IF(OR($A17="",N$4=""),"",IFERROR(INDEX(Submissions!$L$5:$L$304,MATCH(N$4&"|"&N$5&"|"&$A17,Submissions!$Q$5:$Q$304,0)),"NO DATA"))
A18: =IF(Baseline!A31="","",Baseline!A31) | B18: =IF($A18="","",Baseline!B31) | C18: =IF($A18="","",Baseline!C31) | D18: =IF($A18="","",IF(Baseline!E31="","",Baseline!E31)) | E18: =IF(OR($A18="",E$4=""),"",IFERROR(INDEX(Submissions!$L$5:$L$304,MATCH(E$4&"|"&E$5&"|"&$A18,Submissions!$Q$5:$Q$304,0)),"NO DATA")) | F18: =IF(OR($A18="",F$4=""),"",IFERROR(INDEX(Submissions!$L$5:$L$304,MATCH(F$4&"|"&F$5&"|"&$A18,Submissions!$Q$5:$Q$304,0)),"NO DATA")) | G18: =IF(OR($A18="",G$4=""),"",IFERROR(INDEX(Submissions!$L$5:$L$304,MATCH(G$4&"|"&G$5&"|"&$A18,Submissions!$Q$5:$Q$304,0)),"NO DATA")) | H18: =IF(OR($A18="",H$4=""),"",IFERROR(INDEX(Submissions!$L$5:$L$304,MATCH(H$4&"|"&H$5&"|"&$A18,Submissions!$Q$5:$Q$304,0)),"NO DATA")) | I18: =IF(OR($A18="",I$4=""),"",IFERROR(INDEX(Submissions!$L$5:$L$304,MATCH(I$4&"|"&I$5&"|"&$A18,Submissions!$Q$5:$Q$304,0)),"NO DATA")) | J18: =IF(OR($A18="",J$4=""),"",IFERROR(INDEX(Submissions!$L$5:$L$304,MATCH(J$4&"|"&J$5&"|"&$A18,Submissions!$Q$5:$Q$304,0)),"NO DATA")) | K18: =IF(OR($A18="",K$4=""),"",IFERROR(INDEX(Submissions!$L$5:$L$304,MATCH(K$4&"|"&K$5&"|"&$A18,Submissions!$Q$5:$Q$304,0)),"NO DATA")) | L18: =IF(OR($A18="",L$4=""),"",IFERROR(INDEX(Submissions!$L$5:$L$304,MATCH(L$4&"|"&L$5&"|"&$A18,Submissions!$Q$5:$Q$304,0)),"NO DATA")) | ... N18: =IF(OR($A18="",N$4=""),"",IFERROR(INDEX(Submissions!$L$5:$L$304,MATCH(N$4&"|"&N$5&"|"&$A18,Submissions!$Q$5:$Q$304,0)),"NO DATA"))
... A36: =IF(Baseline!A49="","",Baseline!A49) | B36: =IF($A36="","",Baseline!B49) | C36: =IF($A36="","",Baseline!C49) | D36: =IF($A36="","",IF(Baseline!E49="","",Baseline!E49)) | E36: =IF(OR($A36="",E$4=""),"",IFERROR(INDEX(Submissions!$L$5:$L$304,MATCH(E$4&"|"&E$5&"|"&$A36,Submissions!$Q$5:$Q$304,0)),"NO DATA")) | F36: =IF(OR($A36="",F$4=""),"",IFERROR(INDEX(Submissions!$L$5:$L$304,MATCH(F$4&"|"&F$5&"|"&$A36,Submissions!$Q$5:$Q$304,0)),"NO DATA")) | G36: =IF(OR($A36="",G$4=""),"",IFERROR(INDEX(Submissions!$L$5:$L$304,MATCH(G$4&"|"&G$5&"|"&$A36,Submissions!$Q$5:$Q$304,0)),"NO DATA")) | H36: =IF(OR($A36="",H$4=""),"",IFERROR(INDEX(Submissions!$L$5:$L$304,MATCH(H$4&"|"&H$5&"|"&$A36,Submissions!$Q$5:$Q$304,0)),"NO DATA")) | I36: =IF(OR($A36="",I$4=""),"",IFERROR(INDEX(Submissions!$L$5:$L$304,MATCH(I$4&"|"&I$5&"|"&$A36,Submissions!$Q$5:$Q$304,0)),"NO DATA")) | J36: =IF(OR($A36="",J$4=""),"",IFERROR(INDEX(Submissions!$L$5:$L$304,MATCH(J$4&"|"&J$5&"|"&$A36,Submissions!$Q$5:$Q$304,0)),"NO DATA")) | K36: =IF(OR($A36="",K$4=""),"",IFERROR(INDEX(Submissions!$L$5:$L$304,MATCH(K$4&"|"&K$5&"|"&$A36,Submissions!$Q$5:$Q$304,0)),"NO DATA")) | L36: =IF(OR($A36="",L$4=""),"",IFERROR(INDEX(Submissions!$L$5:$L$304,MATCH(L$4&"|"&L$5&"|"&$A36,Submissions!$Q$5:$Q$304,0)),"NO DATA")) | ... N36: =IF(OR($A36="",N$4=""),"",IFERROR(INDEX(Submissions!$L$5:$L$304,MATCH(N$4&"|"&N$5&"|"&$A36,Submissions!$Q$5:$Q$304,0)),"NO DATA"))
D38: RED lines | E38: =IF(E$4="","",COUNTIF(E7:E36,"RED")) | F38: =IF(F$4="","",COUNTIF(F7:F36,"RED")) | G38: =IF(G$4="","",COUNTIF(G7:G36,"RED")) | H38: =IF(H$4="","",COUNTIF(H7:H36,"RED")) | I38: =IF(I$4="","",COUNTIF(I7:I36,"RED")) | J38: =IF(J$4="","",COUNTIF(J7:J36,"RED")) | K38: =IF(K$4="","",COUNTIF(K7:K36,"RED")) | L38: =IF(L$4="","",COUNTIF(L7:L36,"RED")) | ... N38: =IF(N$4="","",COUNTIF(N7:N36,"RED"))
D39: YELLOW lines | E39: =IF(E$4="","",COUNTIF(E7:E36,"YELLOW")) | F39: =IF(F$4="","",COUNTIF(F7:F36,"YELLOW")) | G39: =IF(G$4="","",COUNTIF(G7:G36,"YELLOW")) | H39: =IF(H$4="","",COUNTIF(H7:H36,"YELLOW")) | I39: =IF(I$4="","",COUNTIF(I7:I36,"YELLOW")) | J39: =IF(J$4="","",COUNTIF(J7:J36,"YELLOW")) | K39: =IF(K$4="","",COUNTIF(K7:K36,"YELLOW")) | L39: =IF(L$4="","",COUNTIF(L7:L36,"YELLOW")) | ... N39: =IF(N$4="","",COUNTIF(N7:N36,"YELLOW"))
D40: CLEARED lines | E40: =IF(E$4="","",COUNTIF(E7:E36,"CLEARED")) | F40: =IF(F$4="","",COUNTIF(F7:F36,"CLEARED")) | G40: =IF(G$4="","",COUNTIF(G7:G36,"CLEARED")) | H40: =IF(H$4="","",COUNTIF(H7:H36,"CLEARED")) | I40: =IF(I$4="","",COUNTIF(I7:I36,"CLEARED")) | J40: =IF(J$4="","",COUNTIF(J7:J36,"CLEARED")) | K40: =IF(K$4="","",COUNTIF(K7:K36,"CLEARED")) | L40: =IF(L$4="","",COUNTIF(L7:L36,"CLEARED")) | ... N40: =IF(N$4="","",COUNTIF(N7:N36,"CLEARED"))
D41: Overall status | E41: =IF(E$4="","",IF(COUNTIF(E7:E36,"NO DATA")>0,"INCOMPLETE",IF(E38>0,"RED",IF(E39>0,"YELLOW","GREEN")))) | F41: =IF(F$4="","",IF(COUNTIF(F7:F36,"NO DATA")>0,"INCOMPLETE",IF(F38>0,"RED",IF(F39>0,"YELLOW","GREEN")))) | G41: =IF(G$4="","",IF(COUNTIF(G7:G36,"NO DATA")>0,"INCOMPLETE",IF(G38>0,"RED",IF(G39>0,"YELLOW","GREEN")))) | H41: =IF(H$4="","",IF(COUNTIF(H7:H36,"NO DATA")>0,"INCOMPLETE",IF(H38>0,"RED",IF(H39>0,"YELLOW","GREEN")))) | I41: =IF(I$4="","",IF(COUNTIF(I7:I36,"NO DATA")>0,"INCOMPLETE",IF(I38>0,"RED",IF(I39>0,"YELLOW","GREEN")))) | J41: =IF(J$4="","",IF(COUNTIF(J7:J36,"NO DATA")>0,"INCOMPLETE",IF(J38>0,"RED",IF(J39>0,"YELLOW","GREEN")))) | K41: =IF(K$4="","",IF(COUNTIF(K7:K36,"NO DATA")>0,"INCOMPLETE",IF(K38>0,"RED",IF(K39>0,"YELLOW","GREEN")))) | L41: =IF(L$4="","",IF(COUNTIF(L7:L36,"NO DATA")>0,"INCOMPLETE",IF(L38>0,"RED",IF(L39>0,"YELLOW","GREEN")))) | ... N41: =IF(N$4="","",IF(COUNTIF(N7:N36,"NO DATA")>0,"INCOMPLETE",IF(N38>0,"RED",IF(N39>0,"YELLOW","GREEN"))))
D42: Eligible for evaluation | E42: =IF(E$4="","",IF(E41="GREEN","YES","NO")) | F42: =IF(F$4="","",IF(F41="GREEN","YES","NO")) | G42: =IF(G$4="","",IF(G41="GREEN","YES","NO")) | H42: =IF(H$4="","",IF(H41="GREEN","YES","NO")) | I42: =IF(I$4="","",IF(I41="GREEN","YES","NO")) | J42: =IF(J$4="","",IF(J41="GREEN","YES","NO")) | K42: =IF(K$4="","",IF(K41="GREEN","YES","NO")) | L42: =IF(L$4="","",IF(L41="GREEN","YES","NO")) | ... N42: =IF(N$4="","",IF(N41="GREEN","YES","NO"))

Sheet Evaluation
A1: Commercial Evaluation (RFQ quantities, ex-VAT, SAR)
A2: Evaluated total counts eligible suppliers only. Indicative total shows all bids for reference; not for award.
A4: =Baseline!B11 | B4: =Baseline!D11 | C4: =Baseline!C11
A5: =Baseline!B12 | B5: =Baseline!D12 | C5: =Baseline!C12
A6: =Baseline!B13 | B6: =Baseline!D13 | C6: =Baseline!C13
A8: Supplier | B8: Eligible | C8: Rate item 1 | D8: Rate item 2 | E8: Rate item 3 | F8: Quoted total @ RFQ qty | G8: Adjustments | H8: Evaluated total (eligible) | I8: Rank | J8: Indicative total (all bids) | K8: Indicative rank | L8: Note
A9: =IF('Compliance Matrix'!E4="","",'Compliance Matrix'!E4) | B9: =IF(A9="","",'Compliance Matrix'!E42) | F9: =IF(A9="","",IF(COUNT(C9:E9)<3,"Incomplete",C9*$B$4+D9*$B$5+E9*$B$6)) | H9: =IF(A9="","",IF(B9<>"YES","Not eligible",IF(ISNUMBER(F9),F9+N(G9),"Incomplete"))) | I9: =IF(ISNUMBER(H9),COUNTIF($H$9:$H$18,"<"&H9)+1,"") | J9: =IF(A9="","",IF(ISNUMBER(F9),F9+N(G9),"Incomplete")) | K9: =IF(ISNUMBER(J9),COUNTIF($J$9:$J$18,"<"&J9)+1,"")
A10: =IF('Compliance Matrix'!F4="","",'Compliance Matrix'!F4) | B10: =IF(A10="","",'Compliance Matrix'!F42) | F10: =IF(A10="","",IF(COUNT(C10:E10)<3,"Incomplete",C10*$B$4+D10*$B$5+E10*$B$6)) | H10: =IF(A10="","",IF(B10<>"YES","Not eligible",IF(ISNUMBER(F10),F10+N(G10),"Incomplete"))) | I10: =IF(ISNUMBER(H10),COUNTIF($H$9:$H$18,"<"&H10)+1,"") | J10: =IF(A10="","",IF(ISNUMBER(F10),F10+N(G10),"Incomplete")) | K10: =IF(ISNUMBER(J10),COUNTIF($J$9:$J$18,"<"&J10)+1,"")
A11: =IF('Compliance Matrix'!G4="","",'Compliance Matrix'!G4) | B11: =IF(A11="","",'Compliance Matrix'!G42) | F11: =IF(A11="","",IF(COUNT(C11:E11)<3,"Incomplete",C11*$B$4+D11*$B$5+E11*$B$6)) | H11: =IF(A11="","",IF(B11<>"YES","Not eligible",IF(ISNUMBER(F11),F11+N(G11),"Incomplete"))) | I11: =IF(ISNUMBER(H11),COUNTIF($H$9:$H$18,"<"&H11)+1,"") | J11: =IF(A11="","",IF(ISNUMBER(F11),F11+N(G11),"Incomplete")) | K11: =IF(ISNUMBER(J11),COUNTIF($J$9:$J$18,"<"&J11)+1,"")
A12: =IF('Compliance Matrix'!H4="","",'Compliance Matrix'!H4) | B12: =IF(A12="","",'Compliance Matrix'!H42) | F12: =IF(A12="","",IF(COUNT(C12:E12)<3,"Incomplete",C12*$B$4+D12*$B$5+E12*$B$6)) | H12: =IF(A12="","",IF(B12<>"YES","Not eligible",IF(ISNUMBER(F12),F12+N(G12),"Incomplete"))) | I12: =IF(ISNUMBER(H12),COUNTIF($H$9:$H$18,"<"&H12)+1,"") | J12: =IF(A12="","",IF(ISNUMBER(F12),F12+N(G12),"Incomplete")) | K12: =IF(ISNUMBER(J12),COUNTIF($J$9:$J$18,"<"&J12)+1,"")
A13: =IF('Compliance Matrix'!I4="","",'Compliance Matrix'!I4) | B13: =IF(A13="","",'Compliance Matrix'!I42) | F13: =IF(A13="","",IF(COUNT(C13:E13)<3,"Incomplete",C13*$B$4+D13*$B$5+E13*$B$6)) | H13: =IF(A13="","",IF(B13<>"YES","Not eligible",IF(ISNUMBER(F13),F13+N(G13),"Incomplete"))) | I13: =IF(ISNUMBER(H13),COUNTIF($H$9:$H$18,"<"&H13)+1,"") | J13: =IF(A13="","",IF(ISNUMBER(F13),F13+N(G13),"Incomplete")) | K13: =IF(ISNUMBER(J13),COUNTIF($J$9:$J$18,"<"&J13)+1,"")
A14: =IF('Compliance Matrix'!J4="","",'Compliance Matrix'!J4) | B14: =IF(A14="","",'Compliance Matrix'!J42) | F14: =IF(A14="","",IF(COUNT(C14:E14)<3,"Incomplete",C14*$B$4+D14*$B$5+E14*$B$6)) | H14: =IF(A14="","",IF(B14<>"YES","Not eligible",IF(ISNUMBER(F14),F14+N(G14),"Incomplete"))) | I14: =IF(ISNUMBER(H14),COUNTIF($H$9:$H$18,"<"&H14)+1,"") | J14: =IF(A14="","",IF(ISNUMBER(F14),F14+N(G14),"Incomplete")) | K14: =IF(ISNUMBER(J14),COUNTIF($J$9:$J$18,"<"&J14)+1,"")
A15: =IF('Compliance Matrix'!K4="","",'Compliance Matrix'!K4) | B15: =IF(A15="","",'Compliance Matrix'!K42) | F15: =IF(A15="","",IF(COUNT(C15:E15)<3,"Incomplete",C15*$B$4+D15*$B$5+E15*$B$6)) | H15: =IF(A15="","",IF(B15<>"YES","Not eligible",IF(ISNUMBER(F15),F15+N(G15),"Incomplete"))) | I15: =IF(ISNUMBER(H15),COUNTIF($H$9:$H$18,"<"&H15)+1,"") | J15: =IF(A15="","",IF(ISNUMBER(F15),F15+N(G15),"Incomplete")) | K15: =IF(ISNUMBER(J15),COUNTIF($J$9:$J$18,"<"&J15)+1,"")
A16: =IF('Compliance Matrix'!L4="","",'Compliance Matrix'!L4) | B16: =IF(A16="","",'Compliance Matrix'!L42) | F16: =IF(A16="","",IF(COUNT(C16:E16)<3,"Incomplete",C16*$B$4+D16*$B$5+E16*$B$6)) | H16: =IF(A16="","",IF(B16<>"YES","Not eligible",IF(ISNUMBER(F16),F16+N(G16),"Incomplete"))) | I16: =IF(ISNUMBER(H16),COUNTIF($H$9:$H$18,"<"&H16)+1,"") | J16: =IF(A16="","",IF(ISNUMBER(F16),F16+N(G16),"Incomplete")) | K16: =IF(ISNUMBER(J16),COUNTIF($J$9:$J$18,"<"&J16)+1,"")
A17: =IF('Compliance Matrix'!M4="","",'Compliance Matrix'!M4) | B17: =IF(A17="","",'Compliance Matrix'!M42) | F17: =IF(A17="","",IF(COUNT(C17:E17)<3,"Incomplete",C17*$B$4+D17*$B$5+E17*$B$6)) | H17: =IF(A17="","",IF(B17<>"YES","Not eligible",IF(ISNUMBER(F17),F17+N(G17),"Incomplete"))) | I17: =IF(ISNUMBER(H17),COUNTIF($H$9:$H$18,"<"&H17)+1,"") | J17: =IF(A17="","",IF(ISNUMBER(F17),F17+N(G17),"Incomplete")) | K17: =IF(ISNUMBER(J17),COUNTIF($J$9:$J$18,"<"&J17)+1,"")
